Workbook

Sheet NESN.SW_Balance Sheet
A1: Balance Sheet
A3: Balance Sheet | B3: 45657 | C3: 45291 | D3: 44926 | E3: 44561
A4: Treasury Shares Number | B4: 47284961 | C4: 48693709 | D4: 81900000 | E4: 55407701
A5: Ordinary Shares Number | B5: 2572715039 | C5: 2621306291 | D5: 2668100000 | E5: 2759592299
A6: Share Issued | B6: 2620000000 | C6: 2670000000 | D6: 2750000000 | E6: 2815000000
A7: Total Debt | B7: 63560000000 | C7: 55241000000 | D7: 54312000000 | E7: 46574000000
A8: Tangible Book Value | B8: -13923000000 | C8: -11176000000 | D8: -9517000000 | E8: -95000000
A9: Invested Capital | B9: 35917000000 | C9: 35742000000 | D9: 41982000000 | E9: 53140000000
A10: Working Capital | B10: -7675000000 | C10: -6227000000 | D10: -4914000000 | E10: -763000000
A11: Net Tangible Assets | B11: -13923000000 | C11: -11176000000 | D11: -9517000000 | E11: -95000000
A12: Common Stock Equity | B12: 35917000000 | C12: 35742000000 | D12: 41982000000 | E12: 53140000000
A13: Total Capitalization | B13: 35917000000 | C13: 35742000000 | D13: 41982000000 | E13: 53140000000
A14: Total Equity Gross Minority Interest | B14: 36693000000 | C14: 36387000000 | D14: 42792000000 | E14: 53727000000
... A39: Non Current Deferred Taxes Assets | B39: 995000000 | C39: 1181000000 | D39: 1043000000 | E39: 1258000000
A40: Financial Assets | B40: 84000000 | C40: 130000000 | D40: 0
A41: Investmentin Financial Assets | B41: 3650000000 | C41: 2947000000 | D41: 3253000000 | E41: 2824000000
A42: Long Term Equity Investment | B42: 14326000000 | C42: 13088000000 | D42: 13023000000 | E42: 11806000000
A43: Investmentsin Joint Venturesat Cost | B43: 2231000000 | C43: 1970000000 | D43: 1820000000 | E43: 1707000000
A44: Investmentsin Associatesat Cost | B44: 12095000000 | C44: 11118000000 | D44: 11203000000 | E44: 10099000000
A45: Goodwill And Other Intangible Assets | B45: 49840000000 | C45: 46918000000 | D45: 51499000000 | E45: 53235000000
A46: Other Intangible Assets | B46: 19245000000 | C46: 18225000000 | D46: 20237000000 | E46: 22223000000
A47: Goodwill | B47: 30595000000 | C47: 28693000000 | D47: 31262000000 | E47: 31012000000
A48: Net PPE | B48: 33706000000 | C48: 30467000000 | D48: 30141000000 | E48: 28345000000
A49: Accumulated Depreciation | B49: -30344000000 | C49: -27981000000 | D49: -29019000000 | E49: -28382000000
A50: Gross PPE | B50: 64050000000 | C50: 58448000000 | D50: 59160000000 | E50: 56727000000
A51: Construction In Progress | B51: 7277000000 | C51: 7464000000 | D51: 6527000000 | E51: 4704000000
A52: Other Properties | B52: 345000000 | C52: 305000000 | D52: 246000000 | E52: 230000000
... A72: Cash And Cash Equivalents | B72: 5556000000 | C72: 4816000000 | D72: 5511000000 | E72: 6988000000
A73: Cash Equivalents | C73: 2501000000 | D73: 3045000000 | E73: 4303000000
A74: Cash Financial | C74: 2315000000 | D74: 2466000000 | E74: 2685000000

Sheet NESN.SW_Income Statement
A1: Income Statement
B3: 45657 | C3: 45291 | D3: 44926 | E3: 44561
A4: Tax Effect Of Unusual Items | B4: -222250000 | C4: -292656000 | D4: -708504000 | E4: -679459000
A5: Tax Rate For Calcs | B5: 0.25 | C5: 0.182 | D5: 0.212 | E5: 0.209
A6: Normalized EBITDA | B6: 19551000000 | C6: 19412000000 | D6: 18782000000 | E6: 17927000000
A7: Total Unusual Items | B7: -889000000 | C7: -1608000000 | D7: -2706000000 | E7: -2730000000
A8: Total Unusual Items Excluding Goodwill | B8: -889000000 | C8: -1608000000 | D8: -3342000000 | E8: -3251000000
A9: Net Income From Continuing Operation Net Minority Interest | B9: 10884000000 | C9: 11209000000 | D9: 9270000000 | E9: 16905000000
A10: Reconciled Depreciation | B10: 3582000000 | C10: 3458000000 | D10: 3541000000 | E10: 3440000000
A11: Reconciled Cost Of Revenue | B11: 48670000000 | C11: 50328000000 | D11: 51745000000 | E11: 45468000000
A12: EBITDA | B12: 18662000000 | C12: 17804000000 | D12: 16076000000 | E12: 15197000000
A13: EBIT | B13: 15080000000 | C13: 14346000000 | D13: 12535000000 | E13: 11757000000
A14: Net Interest Income | B14: -1485000000 | C14: -1360000000 | D14: -1040000000 | E14: -873000000
A15: Interest Expense | B15: 1841000000 | C15: 1643000000 | D15: 1249000000 | E15: 951000000
... A31: Net Income Continuous Operations | B31: 11174000000 | C31: 11509000000 | D31: 9596000000 | E31: 17196000000
A32: Tax Burden | B32: =1-B28/B34 -> 0.17788353 | C32: =1-C28/C34 -> 0.11761001 | D32: =1-D28/D34 -> 0.17862839 | E32: =1-E28/E34 -> -0.56440866
A33: Tax Provision | B33: 3314000000 | C33: 2314000000 | D33: 2730000000 | E33: 2261000000
A34: Pretax Income | B34: 13239000000 | C34: 12703000000 | D34: 11286000000 | E34: 10806000000
A35: Other Non Operating Income Expenses | C35: 295000000 | D35: 320000000 | E35: 441000000
A36: Special Income Charges | B36: -889000000 | C36: -1608000000 | D36: -3342000000 | E36: -3251000000
A37: Other Special Charges | B37: -2000000 | C37: 238000000 | D37: 343000000 | E37: 326000000
A38: Impairment Of Capital Assets | B38: 580000000 | C38: 647000000 | D38: 2090000000 | E38: 2093000000
A39: Restructuring And Mergern Acquisition | B39: 311000000 | C39: 723000000 | D39: 273000000 | E39: 311000000
A40: Net Non Operating Interest Income Expense | B40: -1485000000 | C40: -1360000000 | D40: -1040000000 | E40: -873000000
A41: Total Other Finance Cost | B41: 2000000 | C41: 1000000 | D41: 1000000 | E41: 2000000
A42: Interest Expense Non Operating | B42: 1841000000 | C42: 1643000000 | D42: 1249000000 | E42: 951000000
A43: Interest Income Non Operating | B43: 358000000 | C43: 284000000 | D43: 210000000 | E43: 80000000
A44: Operating Income | B44: 15613000000 | C44: 15671000000 | D44: 15668000000 | E44: 14930000000
A45: Operating Expense | B45: 27437000000 | C45: 27352000000 | D45: 27367000000 | E45: 27072000000
A46: Other Operating Expenses | B46: 399000000 | C46: 653000000 | D46: 726000000 | E46: 801000000
A47: Research And Development | B47: 1667000000 | C47: 1656000000 | D47: 1696000000 | E47: 1670000000
... A53: Operating Revenue | B53: 91720000000 | C53: 93351000000 | D53: 94780000000 | E53: 87470000000

Sheet NESN.SW_Cash Flow
A1: Cashflow Statement
B3: 45657 | C3: 45291 | D3: 44926 | E3: 44561
A4: Free Cash Flow | B4: 10712000000 | C4: 9738000000 | D4: 6546000000 | E4: 8523000000
A5: Repurchase Of Capital Stock | B5: -4678000000 | C5: -5234000000
A6: Repayment Of Debt | B6: -5055000000 | C6: -3589000000 | D6: -3283000000 | E6: -4474000000
A7: Issuance Of Debt | B7: 7992000000 | C7: 9806000000 | D7: 10936000000 | E7: 11339000000
A8: Capital Expenditure | B8: -5963000000 | C8: -6203000000 | D8: -5361000000 | E8: -5341000000
A9: End Cash Position | B9: 5556000000 | C9: 4816000000 | D9: 5511000000 | E9: 6992000000
A10: Other Cash Adjustment Outside Changein Cash | B10: -2000000
A11: Beginning Cash Position | B11: 4816000000 | C11: 5511000000 | D11: 6992000000 | E11: 5235000000
A12: Effect Of Exchange Rate Changes | B12: 53000000 | C12: -682000000 | D12: -100000000 | E12: 89000000
A13: Changes In Cash | B13: 689000000 | C13: -13000000 | D13: -1381000000 | E13: 1668000000
A14: Financing Cash Flow | B14: -7362000000 | C14: -9758000000 | D14: -11385000000 | E14: -9152000000
A15: Net Other Financing Charges | B15: -27000000 | C15: -52000000 | D15: -605000000 | E15: -601000000
A16: Cash Dividends Paid | B16: -7816000000 | C16: -7829000000 | D16: -7618000000 | E16: -7681000000
A17: Common Stock Dividend Paid | B17: -7816000000 | C17: -7829000000 | D17: -7618000000 | E17: -7681000000
A18: Net Common Stock Issuance | B18: -4678000000 | C18: -5234000000 | D18: -10679000000 | E18: -6548000000
A19: Common Stock Payments | B19: -4678000000 | C19: -5234000000
A20: Net Issuance Payments Of Debt | B20: 5333000000 | C20: 3680000000 | D20: 7801000000 | E20: 5980000000
A21: Net Short Term Debt Issuance | B21: 2396000000 | C21: -2537000000 | D21: 148000000 | E21: -885000000
A22: Net Long Term Debt Issuance | B22: 2937000000 | C22: 6217000000 | D22: 7653000000 | E22: 6865000000
A23: Long Term Debt Payments | B23: -5055000000 | C23: -3589000000 | D23: -3283000000 | E23: -4474000000
A24: Long Term Debt Issuance | B24: 7992000000 | C24: 9806000000 | D24: 10936000000 | E24: 11339000000
A25: Investing Cash Flow | B25: -8624000000 | C25: -6196000000 | D25: -1903000000 | E25: -3044000000
A26: Net Other Investing Changes | B26: -46000000 | C26: 665000000 | D26: 24000000 | E26: 192000000
A27: Net Investment Purchase And Sale | B27: -1251000000 | C27: -80000000 | D27: 5902000000 | E27: -3610000000
A28: Net Business Purchase And Sale | B28: -1364000000 | C28: -578000000 | D28: -2468000000 | E28: 5715000000
A29: Sale Of Business | C29: 215000000 | D29: 160000000 | E29: 12824000000
A30: Purchase Of Business | B30: -832000000 | C30: -211000000 | D30: -2628000000 | E30: -7109000000
A31: Net Intangibles Purchase And Sale | E31: -461000000
A32: Purchase Of Intangibles | E32: -461000000
A33: Capital Expenditure Reported | B33: -5963000000 | C33: -6203000000 | D33: -5361000000 | E33: -5341000000
A34: Operating Cash Flow | B34: 16675000000 | C34: 15941000000 | D34: 11907000000 | E34: 13864000000
A35: Taxes Refund Paid | B35: -2411000000 | C35: -2801000000 | D35: -3107000000 | E35: -2722000000
A36: Interest Received Cfo | B36: 273000000 | C36: 193000000 | D36: 118000000 | E36: 43000000
A37: Interest Paid Cfo | B37: -1539000000 | C37: -1330000000 | D37: -953000000 | E37: -753000000
A38: Dividend Received Cfo | B38: 759000000 | C38: 699000000 | D38: 608000000 | E38: 651000000
A39: Change In Working Capital | B39: 874000000 | C39: 709000000 | D39: -3647000000 | E39: -600000000
A40: Change In Other Current Assets | B40: -273000000 | C40: -794000000 | D40: -657000000 | E40: -575000000
A41: Change In Accrued Expense | B41: 163000000 | C41: 351000000 | D41: 115000000 | E41: 44000000
...

Sheet DCF
C2: 2021 | D2: 2022 | E2: 2023 | F2: 2024 | G2: 2025 | H2: 2026 | I2: 2027
A3: NESN DCF model
A5: OVERVIEW
A6: Company ticker | B6: NESN
A7: Start Date | B7: 45981
A8: End Date | B8: 46022
A9: Stock price | B9: 79.42
A10: Stock price forecast | B10: =I71 -> 89.299482
A11: Upside | B11: =B10/B9-1 -> 0.1243954
A12: Judgement of valuation | B12: Undervalued
A14: ASSUMPTION
A16: Scenario | D16: 1. Pessimistic case | G16: 2. Base case | J16: 3. Optimistic case
A17: Case selected | B17: 2 | D17: Revenue g % | E17: 0.8 | J17: Revenue g% | K17: 1.1
A18: WACC | B18: =CHOOSE(B17,E18,H18,K18) -> 0.045224968 | D18: WACC | E18: =H18+0.5% -> 0.050224968 | G18: WACC | H18: =WACC!C23 -> 0.045224968 | J18: WACC | K18: =H18-0.3% -> 0.042224968
A19: Terminal Growth Rate | B19: =CHOOSE(B17,E19,H19,K19) -> 0.02 | D19: Terminal Growth Rate | E19: =H19-0.5% -> 0.015 | G19: Terminal Growth Rate | H19: 0.02 | J19: Terminal Growth Rate | K19: =H19+0.3% -> 0.023
A21: INCOME STATEMENT
A22: Revenue | C22: ='NESN.SW_Income Statement'!B52 -> 91720000000 | D22: ='NESN.SW_Income Statement'!C52 -> 93351000000 | E22: ='NESN.SW_Income Statement'!D52 -> 94780000000 | F22: ='NESN.SW_Income Statement'!E52 -> 87470000000 | G22: =F22*(1+G23) -> 8.6186063e+10 | H22: =G22*(1+H23) -> 8.3988412e+10 | I22: =H22*(1+I23) -> 8.0704368e+10
A23: % growth | D23: =D22/C22-1 -> 0.017782381 | E23: =E22/D22-1 -> 0.015307817 | F23: =F22/E22-1 -> -0.077125976 | G23: =AVERAGE(D23:F23) -> -0.014678593 | H23: =AVERAGE(E23:G23) -> -0.025498917 | I23: =AVERAGE(F23:H23) -> -0.039101162
A24: Pessimistic Case | G24: =($E$17*G22)/F22-1 -> -0.21174287 | H24: =($E$17*H22)/G22-1 -> -0.22039913 | I24: =($E$17*I22)/H22-1 -> -0.23128093
A25: Base Case | G25: =G23 -> -0.014678593 | H25: =H23 -> -0.025498917 | I25: =I23 -> -0.039101162
A26: Optimistic Case | G26: =($K$17*G22)/F22-1 -> 0.083853548 | H26: =($K$17*H22)/G22-1 -> 0.071951191 | I26: =($K$17*I22)/H22-1 -> 0.056988722
A28: Gross Profit | C28: ='NESN.SW_Income Statement'!B50 -> 43050000000 | D28: ='NESN.SW_Income Statement'!C50 -> 43023000000 | E28: ='NESN.SW_Income Statement'!D50 -> 43035000000 | F28: ='NESN.SW_Income Statement'!E50 -> 42002000000 | G28: =G22*G29 -> 4.0172956e+10 | H28: =H22*H29 -> 3.9080467e+10 | I28: =I22*I29 -> 3.7641844e+10
A29: % sales | C29: =C28/C22 -> 0.46936328 | D29: =D28/D22 -> 0.46087348 | E29: =E28/E22 -> 0.45405149 | F29: =F28/F22 -> 0.48018749 | G29: =AVERAGE(C29:F29) -> 0.46611893 | H29: =AVERAGE(D29:G29) -> 0.46530785 | I29: =AVERAGE(E29:H29) -> 0.46641644
A31: SG&A Expenses | C31: ='NESN.SW_Income Statement'!B48 -> 25679000000 | D31: ='NESN.SW_Income Statement'!C48 -> 25314000000 | E31: ='NESN.SW_Income Statement'!D48 -> 25236000000 | F31: ='NESN.SW_Income Statement'!E48 -> 25213000000 | G31: =G22*G32 -> 2.3822859e+10 | H31: =H22*H32 -> 2.3140659e+10 | I31: =I22*I32 -> 2.2323637e+10
A32: % sales | C32: =C31/C22 -> 0.27997165 | D32: =D31/D22 -> 0.2711701 | E32: =E31/E22 -> 0.2662587 | F32: =F31/F22 -> 0.2882474 | G32: =AVERAGE(C32:F32) -> 0.27641196 | H32: =AVERAGE(D32:G32) -> 0.27552204 | I32: =AVERAGE(E32:H32) -> 0.27661003
A34: EBIT | C34: ='NESN.SW_Income Statement'!B44 -> 15613000000 | D34: ='NESN.SW_Income Statement'!C44 -> 15671000000 | E34: ='NESN.SW_Income Statement'!D44 -> 15668000000 | F34: ='NESN.SW_Income Statement'!E44 -> 14930000000 | G34: =G22*G35 -> 1.4524347e+10 | H34: =H22*H35 -> 1.4118267e+10 | I34: =I22*I35 -> 1.3570786e+10
A35: % sales | C35: =C34/C22 -> 0.1702246 | D35: =D34/D22 -> 0.1678718 | E35: =E34/E22 -> 0.16530914 | F35: =F34/F22 -> 0.17068709 | G35: =AVERAGE(C35:F35) -> 0.16852316 | H35: =AVERAGE(D35:G35) -> 0.1680978 | I35: =AVERAGE(E35:H35) -> 0.1681543
A37: Income Tax Expense | C37: =C34*'NESN.SW_Income Statement'!B5 -> 3903250000 | D37: =D34*'NESN.SW_Income Statement'!C5 -> 2852122000 | E37: =E34*'NESN.SW_Income Statement'!D5 -> 3321616000 | F37: =F34*'NESN.SW_Income Statement'!E5 -> 3120370000 | G37: =G34*G38 -> 3.0973171e+09 | H37: =H34*H38 -> 2.8810088e+09 | I37: =I34*I38 -> 2.8441399e+09
A38: % Tax rate | C38: ='NESN.SW_Income Statement'!B5 -> 0.25 | D38: ='NESN.SW_Income Statement'!C5 -> 0.182 | E38: ='NESN.SW_Income Statement'!D5 -> 0.212 | F38: ='NESN.SW_Income Statement'!E5 -> 0.209 | G38: =AVERAGE(C38:F38) -> 0.21325 | H38: =AVERAGE(D38:G38) -> 0.2040625 | I38: =AVERAGE(E38:H38) -> 0.20957813
A40: EBIAT | C40: =C34-C37 -> 11709750000 | D40: =D34-D37 -> 12818878000 | E40: =E34-E37 -> 12346384000 | F40: =F34-F37 -> 11809630000 | G40: =G34-G37 -> 1.142703e+10 | H40: =H34-H37 -> 1.1237258e+10 | I40: =I34-I37 -> 1.0726646e+10
A41: %sales | C41: =C40/C22 -> 0.12766845 | D41: =D40/D22 -> 0.13731913 | E41: =E40/E22 -> 0.1302636 | F41: =F40/F22 -> 0.13501349 | G41: =G40/G22 -> 0.13258559 | H41: =H40/H22 -> 0.13379534 | I41: =I40/I22 -> 0.13291283
A44: CASHFLOW STATEMENT
A46: Plus: D&A | C46: ='NESN.SW_Income Statement'!B10 -> 3582000000 | D46: ='NESN.SW_Income Statement'!C10 -> 3458000000 | E46: 3582000000 | F46: ='NESN.SW_Income Statement'!E10 -> 3440000000 | G46: =G22*G47 -> 3.3012965e+09 | H46: =H22*H47 -> 3.2013829e+09 | I46: =I22*I47 -> 3.0978736e+09
A47: % sales | C47: =C46/C22 -> 0.039053642 | D47: =D46/D22 -> 0.037042988 | E47: =E46/E22 -> 0.037792783 | F47: =F46/F22 -> 0.03932777 | G47: =AVERAGE(C47:F47) -> 0.038304296 | H47: =AVERAGE(D47:G47) -> 0.038116959 | I47: =AVERAGE(E47:H47) -> 0.038385452
A49: Less: Capex | C49: =-('NESN.SW_Cash Flow'!B8) -> 5963000000 | D49: =-('NESN.SW_Cash Flow'!C8) -> 6203000000 | E49: =-('NESN.SW_Cash Flow'!D8) -> 5361000000 | F49: =-('NESN.SW_Cash Flow'!E8) -> 5341000000 | G49: =G22*G50 -> 5.3669079e+09 | H49: =H22*H50 -> 5.1724855e+09 | I49: =I22*I50 -> 4.8721305e+09
A50: % sales | C50: =C49/C22 -> 0.065013083 | D50: =D49/D22 -> 0.066448137 | E50: =E49/E22 -> 0.056562566 | F50: =F49/F22 -> 0.061060935 | G50: =AVERAGE(C50:F50) -> 0.06227118 | H50: =AVERAGE(D50:G50) -> 0.061585704 | I50: =AVERAGE(E50:H50) -> 0.060370096
A52: Less: Change in WC | C52: =-('NESN.SW_Cash Flow'!B39) -> -874000000 | D52: =-('NESN.SW_Cash Flow'!C39) -> -709000000 | E52: =-('NESN.SW_Cash Flow'!D39) -> 3647000000 | F52: =-('NESN.SW_Cash Flow'!E39) -> 600000000 | G52: =G22*G53 -> 6.0791522e+08 | H52: =H22*H53 -> 9.4059897e+08 | I52: =I22*I53 -> 1.2830128e+09
A53: % sales | C53: =C52/C22 -> -0.0095290013 | D53: =D52/D22 -> -0.0075949909 | E53: =E52/E22 -> 0.038478582 | F53: =F52/F22 -> 0.0068594947 | G53: =AVERAGE(C53:F53) -> 0.0070535211 | H53: =AVERAGE(D53:G53) -> 0.011199152 | I53: =AVERAGE(E53:H53) -> 0.015897687
A55: Discounted Cash Flow
A57: EBIAT | G57: =G40 -> 1.142703e+10 | H57: =H40 -> 1.1237258e+10 | I57: =I40 -> 1.0726646e+10
...

Sheet WACC
B2: Formula used
B3: Wacc = Re * E/V + Rd*(1-t)*D/V
B4: Re = Rf + Be*(MRP)
B5: V = D + E
B8: Items | C8: Value | D8: Source
B9: Market Equity | C9: 205480000000 | D9: Yahoo Finance
B10: Debt | C10: 51697000000 | D10: Yahoo Finance
B11: Value(E+D) | C11: =SUM(C9:C10) -> 257177000000 | D11: Yahoo Finance
B12: E/V | C12: =C9/SUM(C9:C10) -> 0.7989828 | D12: Yahoo Finance
B13: D/V | C13: =C10/SUM(C9:C10) -> 0.2010172 | D13: Yahoo Finance
B15: Re | C15: =(C16+C17*C18) -> 0.048156
B16: Rf | C16: 0.02564 | D16: Federal Reserve Bank of St.Louis - 10 Year Government yield curve Sweden
B17: Bequity | C17: 0.52 | D17: yahoofinance
B18: MRP | C18: 0.0433 | D18: Damodaran
B20: Rd | C20: 0.0425 | D20: Value Investing.io
B21: 1-t | C21: 0.79 | D21: Corporate tax rate: 20%
B23: WACC | C23: =C12*C15 + C13*C20*C21 -> 0.045224968
